<?xml version="1.0"?>
<robot name="burger_gazebo">

  <!-- ================= MATERIALI ================= -->
  <material name="black"><color rgba="0.05 0.05 0.05 1"/></material>
  <material name="gray"><color rgba="0.6 0.6 0.6 1"/></material>
  <material name="green"><color rgba="0.2 0.8 0.2 1"/></material>
  <material name="blue"><color rgba="0.2 0.2 0.8 1"/></material>
  <material name="semi_black"><color rgba="0 0 0 0.8"/></material>

  <!-- ================= BASE FOOTPRINT ================= -->
  <link name="base_footprint"/>

  <joint name="base_footprint_to_base_link" type="fixed">
    <parent link="base_footprint"/>
    <child link="base_link"/>
    <origin xyz="0.025 0 0.043"/>
  </joint>

  <!-- ================= BASE LINK ================= -->
  <link name="base_link">
    <visual>
      <geometry><box size="0.25 0.17 0.125"/></geometry>
      <origin xyz="0 0 0.0625"/>
      <material name="semi_black"/>
    </visual>

    <collision>
      <geometry><box size="0.25 0.17 0.125"/></geometry>
      <origin xyz="0 0 0.0625"/>
    </collision>

    <inertial>
      <mass value="3.0"/>
      <origin xyz="0 0 0.0625"/>
      <inertia
        ixx="0.011"
        iyy="0.019"
        izz="0.023"
        ixy="0" ixz="0" iyz="0"/>
    </inertial>
  </link>

  <!-- ================= RUOTA SINISTRA ================= -->
  <link name="left_wheel">
    <visual>
      <geometry><cylinder radius="0.035" length="0.02"/></geometry>
      <material name="blue"/>
    </visual>

    <collision>
      <geometry><cylinder radius="0.035" length="0.02"/></geometry>
    </collision>

    <inertial>
      <mass value="0.2"/>
      <inertia ixx="0.0001" iyy="0.0001" izz="0.0001"
               ixy="0" ixz="0" iyz="0"/>
    </inertial>
  </link>

  <joint name="left_wheel_joint" type="continuous">
    <parent link="base_link"/>
    <child link="left_wheel"/>
    <origin xyz="-0.025 0.085 -0.010" rpy="1.570796 0 0"/>
    <axis xyz="0 1 0"/>
  </joint>

  <!-- ================= RUOTA DESTRA ================= -->
  <link name="right_wheel">
    <visual>
      <geometry><cylinder radius="0.035" length="0.02"/></geometry>
      <material name="blue"/>
    </visual>

    <collision>
      <geometry><cylinder radius="0.035" length="0.02"/></geometry>
    </collision>

    <inertial>
      <mass value="0.2"/>
      <inertia ixx="0.0001" iyy="0.0001" izz="0.0001"
               ixy="0" ixz="0" iyz="0"/>
    </inertial>
  </link>

  <joint name="right_wheel_joint" type="continuous">
    <parent link="base_link"/>
    <child link="right_wheel"/>
    <origin xyz="-0.025 -0.085 -0.010" rpy="1.570796 0 0"/>
    <axis xyz="0 1 0"/>
  </joint>

  <!-- ================= SFERA PASSIVA ================= -->
  <link name="front_ball">
    <visual>
      <geometry><sphere radius="0.025"/></geometry>
      <material name="gray"/>
    </visual>

    <collision>
      <geometry><sphere radius="0.025"/></geometry>
    </collision>

    <inertial>
      <mass value="0.05"/>
      <inertia ixx="1e-4" iyy="1e-4" izz="1e-4"/>
    </inertial>
  </link>

  <joint name="front_ball_joint" type="fixed">
    <parent link="base_link"/>
    <child link="front_ball"/>
    <origin xyz="0.093 0 -0.025"/>
  </joint>

  <!-- ================= PLUGIN DI LOCOMOZIONE ================= -->
  <gazebo>
    <plugin name="diff_drive" filename="libgazebo_ros_diff_drive.so">
      <left_joint>left_wheel_joint</left_joint>
      <right_joint>right_wheel_joint</right_joint>
      <wheel_separation>0.20</wheel_separation>
      <wheel_radius>0.035</wheel_radius>
      <command_topic>cmd_vel</command_topic>
      <odometry_topic>odom</odometry_topic>
      <base_frame>base_link</base_frame>
      <odom_frame>odom</odom_frame>
      <publish_odom>true</publish_odom>
      <update_rate>100</update_rate>
    </plugin>
  </gazebo>

</robot>
